<sdf version='1.7'>
  <world name='default'>
    <scene>
      <ambient>0.8 0.8 0.8 1</ambient>
      <shadows>0</shadows>
      <grid>0</grid>
      <background>0.7 0.7 0.7 1</background>
    </scene>
    <model name='course'>
      <static>1</static>
      <link name='course_link'>
        <collision name='course_collision'>
          <geometry>
            <plane>
              <normal>0 0 1</normal>
              <size>4 4</size>
            </plane>
          </geometry>
          <surface>
            <friction>
              <ode>
                <mu>100</mu>
                <mu2>50</mu2>
              </ode>
              <torsional>
                <ode/>
              </torsional>
            </friction>
            <contact>
              <ode/>
            </contact>
            <bounce/>
          </surface>
          <max_contacts>10</max_contacts>
        </collision>
        <visual name='course_visual'>
          <cast_shadows>0</cast_shadows>
          <geometry>
            <plane>
              <normal>0 0 1</normal>
              <size>4 4</size>
            </plane>
          </geometry>
          <material>
            <script>
              <uri>model://turtlebot3_course/course/materials/scripts</uri>
              <uri>model://turtlebot3_course/course/materials/textures</uri>
              <name>course</name>
            </script>
          </material>
        </visual>
        <self_collide>0</self_collide>
        <enable_wind>0</enable_wind>
        <kinematic>0</kinematic>
      </link>
      <pose>0 0 0 0 0 -3.14</pose>
    </model>
    <model name='traffic_light'>
      <link name='traffic_light'>
        <pose>0 0 0 0 -0 0</pose>
        <collision name='collision'>
          <geometry>
            <box>
              <size>0.12 0.025 0.25</size>
            </box>
          </geometry>
          <max_contacts>10</max_contacts>
          <surface>
            <contact>
              <ode/>
            </contact>
            <bounce/>
            <friction>
              <torsional>
                <ode/>
              </torsional>
              <ode/>
            </friction>
          </surface>
        </collision>
        <visual name='visual'>
          <geometry>
            <box>
              <size>0.12 0.025 0.25</size>
            </box>
          </geometry>
          <material>
            <script>
              <uri>model://turtlebot3_course/traffic_light/materials/scripts</uri>
              <uri>model://turtlebot3_course/traffic_light/materials/textures</uri>
              <name>traffic_light_red</name>
            </script>
          </material>
        </visual>
        <self_collide>0</self_collide>
        <enable_wind>0</enable_wind>
        <kinematic>0</kinematic>
      </link>
      <plugin name='traffic_light_plugin' filename='libtraffic_light_plugin.so'/>
      <static>1</static>
      <pose>1.3 -1.95 0.13 0 0 -1.57</pose>
    </model>
    <gravity>0 0 -9.8</gravity>
    <physics name='default_physics' default='0' type='ode'>
      <max_step_size>0.001</max_step_size>
      <real_time_factor>1</real_time_factor>
      <real_time_update_rate>1000</real_time_update_rate>
    </physics>
    <gui fullscreen='0'>
      <camera name='user_camera'>
        <pose>-5.06644 -0.677103 4.39794 0 0.709797 -0.02418</pose>
        <view_controller>orbit</view_controller>
        <projection_type>perspective</projection_type>
      </camera>
    </gui>
    <magnetic_field>6e-06 2.3e-05 -4.2e-05</magnetic_field>
    <atmosphere type='adiabatic'/>
    <audio>
      <device>default</device>
    </audio>
    <wind/>
    <spherical_coordinates>
      <surface_model>EARTH_WGS84</surface_model>
      <latitude_deg>0</latitude_deg>
      <longitude_deg>0</longitude_deg>
      <elevation>0</elevation>
      <heading_deg>0</heading_deg>
    </spherical_coordinates>
    <model name='turtlebot3_manipulation_system'>
      <link name='base_footprint'>
        <inertial>
          <pose>-0.007462 0 0.023362 0 -0 0</pose>
          <mass>1.57603</mass>
          <inertia>
            <ixx>0.0138227</ixx>
            <ixy>-4.75766e-05</ixy>
            <ixz>0.000940284</ixz>
            <iyy>0.0146668</iyy>
            <iyz>-3.54223e-06</iyz>
            <izz>0.0186293</izz>
          </inertia>
        </inertial>
        <collision name='base_footprint_fixed_joint_lump__base_link_collision'>
          <pose>-0.064 0 0.057 0 -0 0</pose>
          <geometry>
            <box>
              <size>0.266 0.266 0.094</size>
            </box>
          </geometry>
          <surface>
            <contact>
              <ode/>
            </contact>
            <friction>
              <ode/>
              <torsional>
                <ode/>
              </torsional>
            </friction>
            <bounce/>
          </surface>
          <max_contacts>10</max_contacts>
        </collision>
        <collision name='base_footprint_fixed_joint_lump__link1_collision_1'>
          <pose>-0.092 0 0.101 0 -0 0</pose>
          <geometry>
            <box>
              <size>0.05 0.05 0.05</size>
            </box>
          </geometry>
          <surface>
            <contact>
              <ode>
                <kp>1e+06</kp>
                <kd>100</kd>
                <max_vel>1</max_vel>
                <min_depth>0.001</min_depth>
              </ode>
            </contact>
            <friction>
              <ode>
                <mu>30</mu>
                <mu2>30</mu2>
              </ode>
              <torsional>
                <ode/>
              </torsional>
            </friction>
            <bounce/>
          </surface>
          <max_contacts>10</max_contacts>
        </collision>
        <collision name='base_footprint_fixed_joint_lump__camera_link_collision_2'>
          <pose>0.078 0 0.107 0 -0 0</pose>
          <geometry>
            <box>
              <size>0.015 0.03 0.027</size>
            </box>
          </geometry>
          <max_contacts>10</max_contacts>
          <surface>
            <contact>
              <ode/>
            </contact>
            <bounce/>
            <friction>
              <torsional>
                <ode/>
              </torsional>
              <ode/>
            </friction>
          </surface>
        </collision>
        <collision name='base_footprint_fixed_joint_lump__caster_back_left_link_collision_3'>
          <pose>-0.177 0.064001 0.005 -1.57 0 0</pose>
          <geometry>
            <box>
              <size>0.03 0.009 0.02</size>
            </box>
          </geometry>
          <surface>
            <contact>
              <ode>
                <kp>1e+06</kp>
                <kd>100</kd>
                <max_vel>1</max_vel>
                <min_depth>0.001</min_depth>
              </ode>
            </contact>
            <friction>
              <ode>
                <mu>0.1</mu>
                <mu2>0.1</mu2>
              </ode>
              <torsional>
                <ode/>
              </torsional>
            </friction>
            <bounce/>
          </surface>
          <max_contacts>10</max_contacts>
        </collision>
        <collision name='base_footprint_fixed_joint_lump__caster_back_right_link_collision_4'>
          <pose>-0.177 -0.063999 0.005 -1.57 0 0</pose>
          <geometry>
            <box>
              <size>0.03 0.009 0.02</size>
            </box>
          </geometry>
          <surface>
            <contact>
              <ode>
                <kp>1e+06</kp>
                <kd>100</kd>
                <max_vel>1</max_vel>
                <min_depth>0.001</min_depth>
              </ode>
            </contact>
            <friction>
              <ode>
                <mu>0.1</mu>
                <mu2>0.1</mu2>
              </ode>
              <torsional>
                <ode/>
              </torsional>
            </friction>
            <bounce/>
          </surface>
          <max_contacts>10</max_contacts>
        </collision>
        <collision name='base_footprint_fixed_joint_lump__base_scan_collision_5'>
          <pose>-0.009 0 0.1255 0 -0 0</pose>
          <geometry>
            <cylinder>
              <length>0.0315</length>
              <radius>0.055</radius>
            </cylinder>
          </geometry>
          <surface>
            <contact>
              <ode/>
            </contact>
            <friction>
              <ode/>
              <torsional>
                <ode/>
              </torsional>
            </friction>
            <bounce/>
          </surface>
          <max_contacts>10</max_contacts>
        </collision>
        <visual name='base_footprint_fixed_joint_lump__base_link_visual'>
          <pose>-0.064 0 0.01 0 -0 0</pose>
          <geometry>
            <mesh>
              <scale>0.001 0.001 0.001</scale>
              <uri>model://turtlebot3_manipulation_description/meshes/turtlebot3_waffle_pi/base.stl</uri>
            </mesh>
          </geometry>
          <material>
            <script>
              <name>Gazebo/DarkGrey</name>
              <uri>file://media/materials/scripts/gazebo.material</uri>
            </script>
          </material>
        </visual>
        <visual name='base_footprint_fixed_joint_lump__link1_visual_1'>
          <pose>-0.092 0 0.101 0 -0 0</pose>
          <geometry>
            <mesh>
              <scale>0.001 0.001 0.001</scale>
              <uri>model://turtlebot3_manipulation_description/meshes/open_manipulator_x/link1.stl</uri>
            </mesh>
          </geometry>
          <material>
            <script>
              <name>Gazebo/DarkGrey</name>
              <uri>file://media/materials/scripts/gazebo.material</uri>
            </script>
          </material>
        </visual>
        <visual name='base_footprint_fixed_joint_lump__base_scan_visual_2'>
          <pose>-0.024 0 0.132 0 -0 0</pose>
          <geometry>
            <mesh>
              <scale>0.001 0.001 0.001</scale>
              <uri>model://turtlebot3_manipulation_description/meshes/turtlebot3_waffle_pi/ladar.stl</uri>
            </mesh>
          </geometry>
          <material>
            <script>
              <name>Gazebo/FlatBlack</name>
              <uri>file://media/materials/scripts/gazebo.material</uri>
            </script>
          </material>
        </visual>
        <sensor name='pi_camera' type='camera'>
          <update_rate>30</update_rate>
          <always_on>1</always_on>
          <visualize>1</visualize>
          <camera>
            <horizontal_fov>1.0856</horizontal_fov>
            <image>
              <width>640</width>
              <height>480</height>
              <format>R8G8B8</format>
            </image>
            <clip>
              <near>0.03</near>
              <far>100</far>
            </clip>
            <noise>
              <type>gaussian</type>
              <mean>0</mean>
              <stddev>0.007</stddev>
            </noise>
          </camera>
          <plugin name='camera_controller' filename='libgazebo_ros_camera.so'>
            <ros>
              <namespace/>
              <remapping>image_raw:=image_raw</remapping>
              <remapping>camera_info:=camera_info</remapping>
            </ros>
          </plugin>
          <pose>0.076 0 0.103 0 -0 0</pose>
        </sensor>
        <sensor name='imu' type='imu'>
          <always_on>1</always_on>
          <update_rate>100</update_rate>
          <visualize>1</visualize>
          <pose>0 0 0.078 0 -0 0</pose>
          <imu/>
        </sensor>
        <sensor name='lds_lfcd_sensor' type='ray'>
          <always_on>1</always_on>
          <update_rate>5</update_rate>
          <visualize>1</visualize>
          <ray>
            <scan>
              <horizontal>
                <samples>360</samples>
                <resolution>1</resolution>
                <min_angle>0</min_angle>
                <max_angle>6.28319</max_angle>
              </horizontal>
              <vertical>
                <samples>1</samples>
                <min_angle>0</min_angle>
                <max_angle>0</max_angle>
              </vertical>
            </scan>
            <range>
              <min>0.12</min>
              <max>3.5</max>
              <resolution>0.015</resolution>
            </range>
            <noise>
              <type>gaussian</type>
              <mean>0</mean>
              <stddev>0.01</stddev>
            </noise>
          </ray>
          <plugin name='gazebo_ros_lds_lfcd_controller' filename='libgazebo_ros_ray_sensor.so'>
            <ros>
              <namespace/>
              <remapping>~/out:=scan</remapping>
            </ros>
            <output_type>sensor_msgs/LaserScan</output_type>
          </plugin>
          <pose>-0.024 0 0.132 0 -0 0</pose>
        </sensor>
        <self_collide>0</self_collide>
        <enable_wind>0</enable_wind>
        <kinematic>0</kinematic>
      </link>
      <joint name='joint1' type='revolute'>
        <pose relative_to='base_footprint'>-0.08 0 0.118 0 -0 0</pose>
        <parent>base_footprint</parent>
        <child>link2</child>
        <axis>
          <xyz>0 0 1</xyz>
          <limit>
            <lower>-2.82743</lower>
            <upper>2.82743</upper>
            <effort>1</effort>
            <velocity>4.8</velocity>
          </limit>
          <dynamics>
            <damping>0.1</damping>
            <friction>0</friction>
            <spring_reference>0</spring_reference>
            <spring_stiffness>0</spring_stiffness>
          </dynamics>
        </axis>
      </joint>
      <link name='link2'>
        <pose relative_to='joint1'>0 0 0 0 -0 0</pose>
        <inertial>
          <pose>-0.000302 0.00054 0.047433 0 -0 0</pose>
          <mass>0.0984068</mass>
          <inertia>
            <ixx>3.45434e-05</ixx>
            <ixy>-1.60311e-08</ixy>
            <ixz>-3.83752e-07</ixz>
            <iyy>3.26893e-05</iyy>
            <iyz>2.85119e-08</iyz>
            <izz>1.88503e-05</izz>
          </inertia>
        </inertial>
        <collision name='link2_collision'>
          <pose>0 0 0.019 0 -0 0</pose>
          <geometry>
            <mesh>
              <scale>0.001 0.001 0.001</scale>
              <uri>model://turtlebot3_manipulation_description/meshes/open_manipulator_x/link2.stl</uri>
            </mesh>
          </geometry>
          <surface>
            <contact>
              <ode>
                <kp>1e+06</kp>
                <kd>100</kd>
                <max_vel>1</max_vel>
                <min_depth>0.001</min_depth>
              </ode>
            </contact>
            <friction>
              <ode>
                <mu>30</mu>
                <mu2>30</mu2>
              </ode>
              <torsional>
                <ode/>
              </torsional>
            </friction>
            <bounce/>
          </surface>
          <max_contacts>10</max_contacts>
        </collision>
        <visual name='link2_visual'>
          <pose>0 0 0.019 0 -0 0</pose>
          <geometry>
            <mesh>
              <scale>0.001 0.001 0.001</scale>
              <uri>model://turtlebot3_manipulation_description/meshes/open_manipulator_x/link2.stl</uri>
            </mesh>
          </geometry>
          <material>
            <script>
              <name>Gazebo/DarkGrey</name>
              <uri>file://media/materials/scripts/gazebo.material</uri>
            </script>
          </material>
        </visual>
        <self_collide>0</self_collide>
        <enable_wind>0</enable_wind>
        <kinematic>0</kinematic>
      </link>
      <joint name='joint2' type='revolute'>
        <pose relative_to='link2'>0 0 0.0595 0 -0 0</pose>
        <parent>link2</parent>
        <child>link3</child>
        <axis>
          <xyz>0 1 0</xyz>
          <limit>
            <lower>-1.79071</lower>
            <upper>1.5708</upper>
            <effort>1</effort>
            <velocity>4.8</velocity>
          </limit>
          <dynamics>
            <damping>0.1</damping>
            <friction>0</friction>
            <spring_reference>0</spring_reference>
            <spring_stiffness>0</spring_stiffness>
          </dynamics>
        </axis>
      </joint>
      <link name='link3'>
        <pose relative_to='joint2'>0 0 0 0 -0 0</pose>
        <inertial>
          <pose>0.010308 0.000377 0.101702 0 -0 0</pose>
          <mass>0.138509</mass>
          <inertia>
            <ixx>0.000330554</ixx>
            <ixy>-9.7941e-08</ixy>
            <ixz>-3.85057e-05</ixz>
            <iyy>0.000342904</iyy>
            <iyz>-1.57175e-06</iyz>
            <izz>6.03465e-05</izz>
          </inertia>
        </inertial>
        <collision name='link3_collision'>
          <pose>0 0 0 0 -0 0</pose>
          <geometry>
            <mesh>
              <scale>0.001 0.001 0.001</scale>
              <uri>model://turtlebot3_manipulation_description/meshes/open_manipulator_x/link3.stl</uri>
            </mesh>
          </geometry>
          <surface>
            <contact>
              <ode>
                <kp>1e+06</kp>
                <kd>100</kd>
                <max_vel>1</max_vel>
                <min_depth>0.001</min_depth>
              </ode>
            </contact>
            <friction>
              <ode>
                <mu>30</mu>
                <mu2>30</mu2>
              </ode>
              <torsional>
                <ode/>
              </torsional>
            </friction>
            <bounce/>
          </surface>
          <max_contacts>10</max_contacts>
        </collision>
        <visual name='link3_visual'>
          <pose>0 0 0 0 -0 0</pose>
          <geometry>
            <mesh>
              <scale>0.001 0.001 0.001</scale>
              <uri>model://turtlebot3_manipulation_description/meshes/open_manipulator_x/link3.stl</uri>
            </mesh>
          </geometry>
          <material>
            <script>
              <name>Gazebo/DarkGrey</name>
              <uri>file://media/materials/scripts/gazebo.material</uri>
            </script>
          </material>
        </visual>
        <self_collide>0</self_collide>
        <enable_wind>0</enable_wind>
        <kinematic>0</kinematic>
      </link>
      <joint name='joint3' type='revolute'>
        <pose relative_to='link3'>0.024 0 0.128 0 -0 0</pose>
        <parent>link3</parent>
        <child>link4</child>
        <axis>
          <xyz>0 1 0</xyz>
          <limit>
            <lower>-0.942478</lower>
            <upper>1.3823</upper>
            <effort>1</effort>
            <velocity>4.8</velocity>
          </limit>
          <dynamics>
            <damping>0.1</damping>
            <friction>0</friction>
            <spring_reference>0</spring_reference>
            <spring_stiffness>0</spring_stiffness>
          </dynamics>
        </axis>
      </joint>
      <link name='link4'>
        <pose relative_to='joint3'>0 0 0 0 -0 0</pose>
        <inertial>
          <pose>0.09091 0.000389 0.000224 0 -0 0</pose>
          <mass>0.132746</mass>
          <inertia>
            <ixx>3.06542e-05</ixx>
            <ixy>-1.27642e-06</ixy>
            <ixz>-2.68744e-07</ixz>
            <iyy>0.000242303</iyy>
            <iyz>1.15595e-08</iyz>
            <izz>0.000251551</izz>
          </inertia>
        </inertial>
        <collision name='link4_collision'>
          <pose>0 0 0 0 -0 0</pose>
          <geometry>
            <mesh>
              <scale>0.001 0.001 0.001</scale>
              <uri>model://turtlebot3_manipulation_description/meshes/open_manipulator_x/link4.stl</uri>
            </mesh>
          </geometry>
          <surface>
            <contact>
              <ode>
                <kp>1e+06</kp>
                <kd>100</kd>
                <max_vel>1</max_vel>
                <min_depth>0.001</min_depth>
              </ode>
            </contact>
            <friction>
              <ode>
                <mu>30</mu>
                <mu2>30</mu2>
              </ode>
              <torsional>
                <ode/>
              </torsional>
            </friction>
            <bounce/>
          </surface>
          <max_contacts>10</max_contacts>
        </collision>
        <visual name='link4_visual'>
          <pose>0 0 0 0 -0 0</pose>
          <geometry>
            <mesh>
              <scale>0.001 0.001 0.001</scale>
              <uri>model://turtlebot3_manipulation_description/meshes/open_manipulator_x/link4.stl</uri>
            </mesh>
          </geometry>
          <material>
            <script>
              <name>Gazebo/DarkGrey</name>
              <uri>file://media/materials/scripts/gazebo.material</uri>
            </script>
          </material>
        </visual>
        <self_collide>0</self_collide>
        <enable_wind>0</enable_wind>
        <kinematic>0</kinematic>
      </link>
      <joint name='joint4' type='revolute'>
        <pose relative_to='link4'>0.124 0 0 0 -0 0</pose>
        <parent>link4</parent>
        <child>link5</child>
        <axis>
          <xyz>0 1 0</xyz>
          <limit>
            <lower>-1.79071</lower>
            <upper>2.04204</upper>
            <effort>1</effort>
            <velocity>4.8</velocity>
          </limit>
          <dynamics>
            <damping>0.1</damping>
            <friction>0</friction>
            <spring_reference>0</spring_reference>
            <spring_stiffness>0</spring_stiffness>
          </dynamics>
        </axis>
      </joint>
      <link name='link5'>
        <pose relative_to='joint4'>0 0 0 0 -0 0</pose>
        <inertial>
          <pose>0.044207 0 0.008914 0 -0 0</pose>
          <mass>0.143276</mass>
          <inertia>
            <ixx>8.08707e-05</ixx>
            <ixy>0</ixy>
            <ixz>-1.01579e-06</ixz>
            <iyy>7.59805e-05</iyy>
            <iyz>0</iyz>
            <izz>9.31274e-05</izz>
          </inertia>
        </inertial>
        <collision name='link5_collision'>
          <pose>0 0 0 0 -0 0</pose>
          <geometry>
            <mesh>
              <scale>0.001 0.001 0.001</scale>
              <uri>model://turtlebot3_manipulation_description/meshes/open_manipulator_x/link5.stl</uri>
            </mesh>
          </geometry>
          <surface>
            <contact>
              <ode>
                <kp>1e+06</kp>
                <kd>100</kd>
                <max_vel>1</max_vel>
                <min_depth>0.001</min_depth>
              </ode>
            </contact>
            <friction>
              <ode>
                <mu>30</mu>
                <mu2>30</mu2>
              </ode>
              <torsional>
                <ode/>
              </torsional>
            </friction>
            <bounce/>
          </surface>
          <max_contacts>10</max_contacts>
        </collision>
        <visual name='link5_visual'>
          <pose>0 0 0 0 -0 0</pose>
          <geometry>
            <mesh>
              <scale>0.001 0.001 0.001</scale>
              <uri>model://turtlebot3_manipulation_description/meshes/open_manipulator_x/link5.stl</uri>
            </mesh>
          </geometry>
          <material>
            <script>
              <name>Gazebo/DarkGrey</name>
              <uri>file://media/materials/scripts/gazebo.material</uri>
            </script>
          </material>
        </visual>
        <visual name='link5_fixed_joint_lump__end_effector_link_visual_1'>
          <pose>0.126 0 0 0 -0 0</pose>
          <geometry>
            <box>
              <size>0.01 0.01 0.01</size>
            </box>
          </geometry>
          <material>
            <script>
              <name>Gazebo/Red</name>
              <uri>file://media/materials/scripts/gazebo.material</uri>
            </script>
          </material>
        </visual>
        <self_collide>0</self_collide>
        <enable_wind>0</enable_wind>
        <kinematic>0</kinematic>
      </link>
      <joint name='gripper_left_joint' type='prismatic'>
        <pose relative_to='link5'>0.0817 0.021 0 0 -0 0</pose>
        <parent>link5</parent>
        <child>gripper_left_link</child>
        <axis>
          <xyz>0 1 0</xyz>
          <limit>
            <lower>-0.01</lower>
            <upper>0.019</upper>
            <effort>1</effort>
            <velocity>4.8</velocity>
          </limit>
          <dynamics>
            <damping>0.1</damping>
            <friction>0</friction>
            <spring_reference>0</spring_reference>
            <spring_stiffness>0</spring_stiffness>
          </dynamics>
        </axis>
      </joint>
      <link name='gripper_left_link'>
        <pose relative_to='gripper_left_joint'>0 0 0 0 -0 0</pose>
        <inertial>
          <pose>0 0 0 0 -0 0</pose>
          <mass>0.001</mass>
          <inertia>
            <ixx>1e-06</ixx>
            <ixy>0</ixy>
            <ixz>0</ixz>
            <iyy>1e-06</iyy>
            <iyz>0</iyz>
            <izz>1e-06</izz>
          </inertia>
        </inertial>
        <collision name='gripper_left_link_collision'>
          <pose>0 0 0 0 -0 0</pose>
          <geometry>
            <mesh>
              <scale>0.001 0.001 0.001</scale>
              <uri>model://turtlebot3_manipulation_description/meshes/open_manipulator_x/gripper_left_palm.stl</uri>
            </mesh>
          </geometry>
          <surface>
            <contact>
              <ode>
                <kp>1e+06</kp>
                <kd>100</kd>
                <max_vel>1</max_vel>
                <min_depth>0.001</min_depth>
              </ode>
            </contact>
            <friction>
              <ode>
                <mu>30</mu>
                <mu2>30</mu2>
              </ode>
              <torsional>
                <ode/>
              </torsional>
            </friction>
            <bounce/>
          </surface>
          <max_contacts>10</max_contacts>
        </collision>
        <visual name='gripper_left_link_visual'>
          <pose>0 0 0 0 -0 0</pose>
          <geometry>
            <mesh>
              <scale>0.001 0.001 0.001</scale>
              <uri>model://turtlebot3_manipulation_description/meshes/open_manipulator_x/gripper_left_palm.stl</uri>
            </mesh>
          </geometry>
          <material>
            <script>
              <name>Gazebo/DarkGrey</name>
              <uri>file://media/materials/scripts/gazebo.material</uri>
            </script>
          </material>
        </visual>
        <self_collide>0</self_collide>
        <enable_wind>0</enable_wind>
        <kinematic>0</kinematic>
      </link>
      <joint name='gripper_right_joint' type='prismatic'>
        <pose relative_to='link5'>0.0817 -0.021 0 0 -0 0</pose>
        <parent>link5</parent>
        <child>gripper_right_link</child>
        <axis>
          <xyz>0 -1 0</xyz>
          <limit>
            <lower>-0.01</lower>
            <upper>0.019</upper>
            <effort>1</effort>
            <velocity>4.8</velocity>
          </limit>
          <dynamics>
            <damping>0.1</damping>
            <friction>0</friction>
            <spring_reference>0</spring_reference>
            <spring_stiffness>0</spring_stiffness>
          </dynamics>
        </axis>
      </joint>
      <link name='gripper_right_link'>
        <pose relative_to='gripper_right_joint'>0 0 0 0 -0 0</pose>
        <inertial>
          <pose>0 0 0 0 -0 0</pose>
          <mass>0.001</mass>
          <inertia>
            <ixx>1e-06</ixx>
            <ixy>0</ixy>
            <ixz>0</ixz>
            <iyy>1e-06</iyy>
            <iyz>0</iyz>
            <izz>1e-06</izz>
          </inertia>
        </inertial>
        <collision name='gripper_right_link_collision'>
          <pose>0 0 0 0 -0 0</pose>
          <geometry>
            <mesh>
              <scale>0.001 0.001 0.001</scale>
              <uri>model://turtlebot3_manipulation_description/meshes/open_manipulator_x/gripper_right_palm.stl</uri>
            </mesh>
          </geometry>
          <surface>
            <contact>
              <ode>
                <kp>1e+06</kp>
                <kd>100</kd>
                <max_vel>1</max_vel>
                <min_depth>0.001</min_depth>
              </ode>
            </contact>
            <friction>
              <ode>
                <mu>30</mu>
                <mu2>30</mu2>
              </ode>
              <torsional>
                <ode/>
              </torsional>
            </friction>
            <bounce/>
          </surface>
          <max_contacts>10</max_contacts>
        </collision>
        <visual name='gripper_right_link_visual'>
          <pose>0 0 0 0 -0 0</pose>
          <geometry>
            <mesh>
              <scale>0.001 0.001 0.001</scale>
              <uri>model://turtlebot3_manipulation_description/meshes/open_manipulator_x/gripper_right_palm.stl</uri>
            </mesh>
          </geometry>
          <material>
            <script>
              <name>Gazebo/DarkGrey</name>
              <uri>file://media/materials/scripts/gazebo.material</uri>
            </script>
          </material>
        </visual>
        <self_collide>0</self_collide>
        <enable_wind>0</enable_wind>
        <kinematic>0</kinematic>
      </link>
      <joint name='wheel_left_joint' type='revolute'>
        <pose relative_to='base_footprint'>0 0.144 0.033 -1.57 0 0</pose>
        <parent>base_footprint</parent>
        <child>wheel_left_link</child>
        <axis>
          <xyz>0 0 1</xyz>
          <limit>
            <lower>-1e+16</lower>
            <upper>1e+16</upper>
          </limit>
          <dynamics>
            <spring_reference>0</spring_reference>
            <spring_stiffness>0</spring_stiffness>
          </dynamics>
        </axis>
      </joint>
      <link name='wheel_left_link'>
        <pose relative_to='wheel_left_joint'>0 0 0 0 -0 0</pose>
        <inertial>
          <pose>0 0 0 0 -0 0</pose>
          <mass>0.0284989</mass>
          <inertia>
            <ixx>1.11756e-05</ixx>
            <ixy>-4.23698e-11</ixy>
            <ixz>-5.93817e-09</ixz>
            <iyy>1.11924e-05</iyy>
            <iyz>-1.44001e-11</iyz>
            <izz>2.07126e-05</izz>
          </inertia>
        </inertial>
        <collision name='wheel_left_link_collision'>
          <pose>0 0 0 0 -0 0</pose>
          <geometry>
            <cylinder>
              <length>0.018</length>
              <radius>0.033</radius>
            </cylinder>
          </geometry>
          <surface>
            <contact>
              <ode>
                <kp>500000</kp>
                <kd>10</kd>
                <max_vel>0.1</max_vel>
                <min_depth>0.001</min_depth>
              </ode>
            </contact>
            <friction>
              <ode>
                <mu>10000</mu>
                <mu2>10000</mu2>
                <fdir1>1 0 0</fdir1>
              </ode>
              <torsional>
                <ode/>
              </torsional>
            </friction>
            <bounce/>
          </surface>
          <max_contacts>10</max_contacts>
        </collision>
        <visual name='wheel_left_link_visual'>
          <pose>0 0 0 1.57 -0 0</pose>
          <geometry>
            <mesh>
              <scale>0.001 0.001 0.001</scale>
              <uri>model://turtlebot3_manipulation_description/meshes/turtlebot3_waffle_pi/left_tire.stl</uri>
            </mesh>
          </geometry>
          <material>
            <script>
              <name>Gazebo/FlatBlack</name>
              <uri>file://media/materials/scripts/gazebo.material</uri>
            </script>
          </material>
        </visual>
        <self_collide>0</self_collide>
        <enable_wind>0</enable_wind>
        <kinematic>0</kinematic>
      </link>
      <joint name='wheel_right_joint' type='revolute'>
        <pose relative_to='base_footprint'>0 -0.144 0.033 -1.57 0 0</pose>
        <parent>base_footprint</parent>
        <child>wheel_right_link</child>
        <axis>
          <xyz>0 0 1</xyz>
          <limit>
            <lower>-1e+16</lower>
            <upper>1e+16</upper>
          </limit>
          <dynamics>
            <spring_reference>0</spring_reference>
            <spring_stiffness>0</spring_stiffness>
          </dynamics>
        </axis>
      </joint>
      <link name='wheel_right_link'>
        <pose relative_to='wheel_right_joint'>0 0 0 0 -0 0</pose>
        <inertial>
          <pose>0 0 0 0 -0 0</pose>
          <mass>0.0284989</mass>
          <inertia>
            <ixx>1.11756e-05</ixx>
            <ixy>-4.23698e-11</ixy>
            <ixz>-5.93817e-09</ixz>
            <iyy>1.11924e-05</iyy>
            <iyz>-1.44001e-11</iyz>
            <izz>2.07126e-05</izz>
          </inertia>
        </inertial>
        <collision name='wheel_right_link_collision'>
          <pose>0 0 0 0 -0 0</pose>
          <geometry>
            <cylinder>
              <length>0.018</length>
              <radius>0.033</radius>
            </cylinder>
          </geometry>
          <surface>
            <contact>
              <ode>
                <kp>500000</kp>
                <kd>10</kd>
                <max_vel>0.1</max_vel>
                <min_depth>0.001</min_depth>
              </ode>
            </contact>
            <friction>
              <ode>
                <mu>10000</mu>
                <mu2>10000</mu2>
                <fdir1>1 0 0</fdir1>
              </ode>
              <torsional>
                <ode/>
              </torsional>
            </friction>
            <bounce/>
          </surface>
          <max_contacts>10</max_contacts>
        </collision>
        <visual name='wheel_right_link_visual'>
          <pose>0 0 0 1.57 -0 0</pose>
          <geometry>
            <mesh>
              <scale>0.001 0.001 0.001</scale>
              <uri>model://turtlebot3_manipulation_description/meshes/turtlebot3_waffle_pi/right_tire.stl</uri>
            </mesh>
          </geometry>
          <material>
            <script>
              <name>Gazebo/FlatBlack</name>
              <uri>file://media/materials/scripts/gazebo.material</uri>
            </script>
          </material>
        </visual>
        <self_collide>0</self_collide>
        <enable_wind>0</enable_wind>
        <kinematic>0</kinematic>
      </link>
      <plugin name='diff_drive' filename='libgazebo_ros_diff_drive.so'>
        <ros>
          <namespace/>
          <remapping>cmd_vel:=cmd_vel</remapping>
          <remapping>odom:=odom</remapping>
        </ros>
        <left_joint>wheel_left_joint</left_joint>
        <right_joint>wheel_right_joint</right_joint>
        <wheel_separation>0.287</wheel_separation>
        <wheel_diameter>0.066</wheel_diameter>
        <max_wheel_torque>20</max_wheel_torque>
        <max_wheel_acceleration>1.0</max_wheel_acceleration>
        <publish_odom>1</publish_odom>
        <publish_odom_tf>1</publish_odom_tf>
        <publish_wheel_tf>0</publish_wheel_tf>
        <odometry_frame>odom</odometry_frame>
        <robot_base_frame>base_footprint</robot_base_frame>
      </plugin>
      <static>0</static>
      <plugin name='gazebo_ros2_control' filename='libgazebo_ros2_control.so'>
        <parameters>/home/weed/team_f_01_ws/install/turtlebot3_manipulation_bringup/share/turtlebot3_manipulation_bringup/config/gazebo_controller_manager.yaml</parameters>
      </plugin>
      <pose>-2 -0.5 0.01 0 -0 0</pose>
    </model>
    <state world_name='default'>
      <sim_time>300 443000000</sim_time>
      <real_time>302 745035094</real_time>
      <wall_time>1746951336 795490060</wall_time>
      <iterations>300443</iterations>
      <model name='course'>
        <pose>0 0 0 0 0 -3.14</pose>
        <scale>1 1 1</scale>
        <link name='course_link'>
          <pose>0 0 0 0 0 -3.14</pose>
          <velocity>0 0 0 0 -0 0</velocity>
          <acceleration>0 0 0 0 -0 0</acceleration>
          <wrench>0 0 0 0 -0 0</wrench>
        </link>
      </model>
      <model name='traffic_light'>
        <pose>0.154749 -1.16751 0.13 0 0 -1.57</pose>
        <scale>1 1 1</scale>
        <link name='traffic_light'>
          <pose>0.154749 -1.16751 0.13 0 0 -1.57</pose>
          <velocity>0 0 0 0 -0 0</velocity>
          <acceleration>0 0 0 0 -0 0</acceleration>
          <wrench>0 0 0 0 -0 0</wrench>
        </link>
      </model>
      <model name='turtlebot3_manipulation_system'>
        <pose>1.12355 0.164094 -0.001008 -2e-06 0.003179 1.5704</pose>
        <scale>1 1 1</scale>
        <link name='base_footprint'>
          <pose>1.12355 0.164094 -0.001008 -2e-06 0.003179 1.5704</pose>
          <velocity>-2e-06 -2e-06 3.9e-05 0.000147 1e-05 1.3e-05</velocity>
          <acceleration>-0 -0 0 0 -0 0</acceleration>
          <wrench>-0 -0 0 0 -0 0</wrench>
        </link>
        <link name='gripper_left_link'>
          <pose>1.10261 0.314772 0.297743 -4e-06 -0.008914 1.57039</pose>
          <velocity>0 0.00016 -0.009338 0.015663 -7e-06 4e-06</velocity>
          <acceleration>3.2e-05 0.20573 -9.38676 0 -0 0</acceleration>
          <wrench>0 0.000206 -0.009387 0 -0 0</wrench>
        </link>
        <link name='gripper_right_link'>
          <pose>1.1446 0.314755 0.297743 -4e-06 -0.008914 1.57039</pose>
          <velocity>0 0.00016 -0.009338 0.015663 -7e-06 4e-06</velocity>
          <acceleration>3.2e-05 0.205902 -9.38674 0 -0 0</acceleration>
          <wrench>0 0.000206 -0.009387 0 -0 0</wrench>
        </link>
        <link name='link2'>
          <pose>1.12351 0.08447 0.117246 -5e-06 0.003178 1.5704</pose>
          <velocity>-0 -1.6e-05 2.7e-05 0.00016 -6e-06 5e-06</velocity>
          <acceleration>-0.00152 0.002193 2.3e-05 0.012998 -0.015647 -0.008726</acceleration>
          <wrench>-0.00015 0.000216 2e-06 0 -0 0</wrench>
        </link>
        <link name='link3'>
          <pose>1.12351 0.084659 0.176745 -4e-06 0.005016 1.57039</pose>
          <velocity>-1e-06 -2.6e-05 2.7e-05 -0.006581 2e-06 4e-06</velocity>
          <acceleration>-0.00228 0.685823 -0.0727 -0.22396 0.575527 -1.48234</acceleration>
          <wrench>-0.000316 0.094993 -0.01007 0 -0 0</wrench>
        </link>
        <link name='link4'>
          <pose>1.12352 0.1093 0.304623 -4e-06 0.061399 1.57039</pose>
          <velocity>-1e-06 0.000816 -0.000135 -0.084695 3.4e-05 3e-06</velocity>
          <acceleration>-0.001597 0.40833 -7.86541 -1.32905 -0.949762 3.00264</acceleration>
          <wrench>-0.000212 0.054204 -1.0441 0 -0 0</wrench>
        </link>
        <link name='link5'>
          <pose>1.12357 0.233067 0.297015 -4e-06 -0.008914 1.57039</pose>
          <velocity>-1e-06 0.000172 -0.010618 0.015664 -7e-06 4e-06</velocity>
          <acceleration>-0.00106 0.072799 -9.98175 -2.33474 -0.018501 -0.178618</acceleration>
          <wrench>-0.000152 0.01043 -1.43014 0 -0 0</wrench>
        </link>
        <link name='wheel_left_link'>
          <pose>0.979547 0.164255 0.031992 -1.57013 -0.011508 1.57039</pose>
          <velocity>1e-06 -8e-06 4.7e-05 0.000214 2.6e-05 8e-06</velocity>
          <acceleration>0.002166 0.000677 0.007221 0.035882 0.016075 -0.010349</acceleration>
          <wrench>6.2e-05 1.9e-05 0.000206 0 -0 0</wrench>
        </link>
        <link name='wheel_right_link'>
          <pose>1.26755 0.164142 0.031992 -1.57014 -0.001807 1.5704</pose>
          <velocity>-1e-06 -5e-06 4.6e-05 0.000139 -7e-06 1e-05</velocity>
          <acceleration>0.001076 -0.000226 0.008755 -0.004326 -0.017001 -0.006394</acceleration>
          <wrench>3.1e-05 -6e-06 0.00025 0 -0 0</wrench>
        </link>
      </model>
    </state>
  </world>
</sdf>
